Workbook

Sheet Lisez-moi
B2: Pignon commun — simulation économique du fonds commun en location
B3: Classeur généré par simulation/export_excel.py à partir de simulation/simulation.py. Document de référence : docs/simulation-economique.md.
B5: Contenu
B6: Hypothèses — tous les paramètres du modèle, modifiables. Chaque valeur porte un nom (colonne F) utilisé dans les formules.
B7: Cotisation — coût annuel attendu par vélo et tarif de location, en formules : il se recalcule quand une hypothèse change.
B8: Fonds 10 ans — projection du fonds en valeur attendue (sans aléa), avec inflation et révision annuelle du tarif.
B9: Scénarios — résultats Monte-Carlo des 37 scénarios critiques (16 940 000 trajectoires de 10 ans graine 2026).
B10: Sensibilité — classement des 22 paramètres selon leur influence sur la marge, et carte de la probabilité de ruine.
B11: Vacance prudente — effet d'un tarif calculé en supposant moins de vélos loués que prévu, face à plusieurs réalités.
B12: Argumentaire — comparaison avec l'achat, un loueur privé et une location publique, prix mensuels liés à la feuille Cotisation, faiblesses d'un loueur classique, raisons de choisir Pignon commun et objections.
B13: Acteurs — les acteurs à rencontrer, ce qu'il faut leur demander, l'argument à mettre en avant et des colonnes de suivi des contacts à remplir.
B15: Légende
... B25: Tous les montants sont illustratifs, sauf les kilométrages, les prix Véligo et les ordres de grandeur du vol et des batteries, sourcés dans la feuille Hypothèses.

Sheet Hypothèses
A1: Hypothèses du modèle
A2: Modifier uniquement la colonne C (texte bleu). Les noms de la colonne F sont utilisés dans les formules des autres feuilles.
A4: Catégorie | B4: Paramètre | C4: Valeur | D4: Unité | E4: Source ou commentaire | F4: Nom
A5: Parc | B5: Vélos à usage léger (vélo classique) | C5: 1200 | D5: vélos | E5: Page, bloc « Passer à l'échelle » | F5: n_leger
A6: Parc | B6: Vélos à usage intensif (vélo-cargo électrique) | C6: 800 | D6: vélos | E6: Page, bloc « Passer à l'échelle » | F6: n_intensif
A7: Parc | B7: Ateliers du réseau | C7: 40 | D7: ateliers | E7: Page, bloc « Passer à l'échelle » | F7: n_ateliers
A8: Usage | B8: Kilométrage annuel, usage léger | C8: 2800 | D8: km/an | E8: Ministère de la Transition écologique et FUB : 6 à 13 km domicile-travail × 200 jours | F8: km_leger
A9: Usage | B9: Kilométrage annuel, usage intensif | C9: 5500 | D9: km/an | E9: Observatoire des Boîtes à Vélo 2024 : 24 km par jour de tournée | F9: km_intensif
A10: Usage | B10: Locataires qui partent chaque année | C10: 0.2 | D10: part | E10: Hypothèse, à mesurer auprès de Véligo et Swapfiets | F10: churn
A11: Usage | B11: Vélos vacants reloués dans l'année | C11: 0.75 | D11: part | E11: Hypothèse, à mesurer auprès de Véligo et Swapfiets | F11: remplissage
A12: Usage | B12: Impayés | C12: 0.02 | D12: part des recettes | E12: Hypothèse | F12: impayes
A13: Usage | B13: Usagers qui sous-déclarent leurs km | C13: 0.05 | D13: part | E13: Hypothèse | F13: fraude_part
A14: Usage | B14: Kilomètres non déclarés par un fraudeur | C14: 0.3 | D14: part | E14: Hypothèse | F14: fraude_sous_declaration
A15: Vélos | B15: Coût de fabrication labellisé, vélo classique | C15: 440 | D15: € | E15: Page, bloc « D'où vient la rente d'usage » (illustratif) | F15: cout_leger
A16: Vélos | B16: Coût de fabrication labellisé, vélo-cargo électrique | C16: 1170 | D16: € | E16: Page (illustratif). Prix publics des cargos français : 3 500 à 7 000 € ; paramètre le plus influent | F16: cout_intensif
... A60: Page initiale | B60: Cotisation annuelle affichée avant correction, usage intensif | C60: 765 | D60: €/an | E60: Page avant le 2026-09-22 | F60: page_intensif

Sheet Cotisation
A1: Coût par vélo et tarif de location
A2: Valeurs attendues en régime courant, calculées à partir de la feuille Hypothèses.
A3: Poste | C3: Usage léger | D3: Usage intensif
A4: Intermédiaires
A5: Occupation d'équilibre du parc | C5: =remplissage/(churn+remplissage-churn*remplissage) -> 0.9375 | D5: =remplissage/(churn+remplissage-churn*remplissage) -> 0.9375
A6: Kilomètres par vélo du parc | C6: =C5*km_leger -> 2625 | D6: =D5*km_intensif -> 5156.25
A7: Âge moyen du parc | C7: =(vie_leger-1)/2 -> 4.5 | D7: =(vie_intensif-1)/2 -> 3.5
A8: Heures d'atelier par vélo du parc | C8: =h_1000km_leger*h_facteur/1000*C6*(1+vieillissement*C7) -> 3.650625 | D8: =h_1000km_intensif*h_facteur/1000*D6*(1+vieillissement*D7) -> 6.84
A9: Coût annuel attendu par vélo du parc
A10: Forfait de suivi | C10: =forfait_suivi*(C5+forfait_vacant*(1-C5)) -> 114.75 | D10: =forfait_suivi*(D5+forfait_vacant*(1-D5)) -> 114.75
A11: Main d'œuvre | C11: =C8*taux_horaire -> 171.57937 | D11: =D8*taux_horaire -> 321.48
A12: Prime de durabilité réparateur | C12: =prime_rep*(C10+C11)*score_moyen/100 -> 53.686758 | D12: =prime_rep*(D10+D11)*score_moyen/100 -> 81.793125
A13: Pièces d'usure | C13: =pieces_km_leger*pieces_facteur*C6 -> 65.625 | D13: =pieces_km_intensif*pieces_facteur*D6 -> 232.03125
A14: Batterie | C14: =0 -> 0 | D14: =batterie_remplacements/vie_intensif*batterie_facteur*batterie_cout -> 85.3125
A15: Rente d'usage fabricant | C15: =IF(taux_financement>0,cout_leger*taux_financement/(1-(1+taux_financement)^(-vie_leger)),cout_leger/vie_leger) -> 44 | D15: =IF(taux_financement>0,cout_intensif*taux_financement/(1-(1+taux_financement)^(-vie_intensif)),cout_intensif/vie_intensif) -> 146.25
A16: Prime de durabilité fabricant | C16: =prime_fab*C15*score_moyen/75 -> 7.04 | D16: =prime_fab*D15*score_moyen/75 -> 23.4
A17: Casse prématurée | C17: =casse_leger*casse_facteur*C5*casse_cout -> 5.625 | D17: =casse_intensif*casse_facteur*D5*casse_cout -> 11.25
A18: Vol : assurance et franchise, moins franchise refacturée | C18: =assurance_taux*cout_leger+vol_leger*(C5+0.3*(1-C5))*assurance_franchise*cout_leger-vol_leger*C5*franchise_client_leger*recouvrement_franchise -> 21.154 | D18: =assurance_taux*cout_intensif+vol_intensif*(D5+0.3*(1-D5))*assurance_franchise*cout_intensif-vol_intensif*D5*franchise_client_intensif*recouvrement_franchise -> 56.22525
A19: Capteur kilométrique | C19: =capteur_cout*(1/vie_leger+capteur_renouvellement) -> 5 | D19: =0 -> 0
A20: Remise en état entre deux locataires | C20: =churn*C5*recond_leger -> 11.25 | D20: =churn*D5*recond_intensif -> 22.5
A21: Coût par vélo du parc | C21: =SUM(C10:C20) -> 499.71013 | D21: =SUM(D10:D20) -> 1094.9921
A22: Tarif de location
A23: Part du coût liée aux kilomètres | C23: =C11+C13+prime_rep*C11*score_moyen/100 -> 269.37551 | D23: =D11+D13+prime_rep*D11*score_moyen/100 -> 613.78875
A24: Part du coût fixe (+ structure fixe répartie) | C24: =C21-C23+gestion_fixe/(n_leger+n_intensif) -> 230.33462 | D24: =D21-D23+gestion_fixe/(n_leger+n_intensif) -> 481.20337
A25: Coefficient gestion + provision | C25: =1+gestion_taux+provision -> 1.14 | D25: =1+gestion_taux+provision -> 1.14
A26: Part fixe du tarif | C26: =C24*C25/(C5*(1-impayes)) -> 285.80296 | D26: =D24*D25/(D5*(1-impayes)) -> 597.085
A27: Part variable du tarif, par km déclaré | C27: =C23*C25/(C5*(1-impayes)*km_leger*(1-fraude_part*fraude_sous_declaration)) -> 0.12119127 | D27: =D23*D25/(D5*(1-impayes)*km_intensif*(1-fraude_part*fraude_sous_declaration)) -> 0.14058128
A28: Cotisation annuelle au kilométrage moyen | C28: =C26+C27*km_leger -> 625.13852 | D28: =D26+D27*km_intensif -> 1370.2821
A29: Cotisation mensuelle | C29: =C28/12 -> 52.094877 | D29: =D28/12 -> 114.19017
A30: Recettes attendues par vélo loué (impayés et fraude déduits) | C30: =(C26+C27*km_leger*(1-fraude_part*fraude_sous_declaration))*(1-impayes) -> 607.64752 | D30: =(D26+D27*km_intensif*(1-fraude_part*fraude_sous_declaration))*(1-impayes) -> 1331.5104
A31: Comparaison
A32: Cotisation affichée sur la page initiale | C32: =page_leger -> 431 | D32: =page_intensif -> 765
A33: Écart avec la page initiale | C33: =C28/C32-1 -> 0.45043741 | D33: =D28/D32-1 -> 0.79121838

Sheet Fonds 10 ans
A1: Projection du fonds commun sur 10 ans (valeurs attendues)
A2: Sans aléa : pour le risque, voir la feuille Scénarios. Le tarif de l'année N est révisé d'après le résultat de l'année N-1, dans la limite des plafonds, si la révision est activée.
A4: Année | B4: 1 | C4: 2 | D4: 3 | E4: 4 | F4: 5 | G4: 6 | H4: 7 | I4: 8 | J4: 9 | K4: 10
A5: Indice d'inflation des coûts | B5: =(1+inflation)^(B4-1) -> 1 | C5: =(1+inflation)^(C4-1) -> 1.02 | D5: =(1+inflation)^(D4-1) -> 1.0404 | E5: =(1+inflation)^(E4-1) -> 1.061208 | F5: =(1+inflation)^(F4-1) -> 1.0824322 | G5: =(1+inflation)^(G4-1) -> 1.1040808 | H5: =(1+inflation)^(H4-1) -> 1.1261624 | I5: =(1+inflation)^(I4-1) -> 1.1486857 | ... K5: =(1+inflation)^(K4-1) -> 1.1950926
A6: Coût du parc léger | B6: =Cotisation!$C$21*n_leger*B5 -> 599652.16 | C6: =Cotisation!$C$21*n_leger*C5 -> 611645.2 | D6: =Cotisation!$C$21*n_leger*D5 -> 623878.11 | E6: =Cotisation!$C$21*n_leger*E5 -> 636355.67 | F6: =Cotisation!$C$21*n_leger*F5 -> 649082.78 | G6: =Cotisation!$C$21*n_leger*G5 -> 662064.44 | H6: =Cotisation!$C$21*n_leger*H5 -> 675305.73 | I6: =Cotisation!$C$21*n_leger*I5 -> 688811.84 | ... K6: =Cotisation!$C$21*n_leger*K5 -> 716639.84
A7: Coût du parc intensif | B7: =Cotisation!$D$21*n_intensif*B5 -> 875993.7 | C7: =Cotisation!$D$21*n_intensif*C5 -> 893513.57 | D7: =Cotisation!$D$21*n_intensif*D5 -> 911383.85 | E7: =Cotisation!$D$21*n_intensif*E5 -> 929611.52 | F7: =Cotisation!$D$21*n_intensif*F5 -> 948203.75 | G7: =Cotisation!$D$21*n_intensif*G5 -> 967167.83 | H7: =Cotisation!$D$21*n_intensif*H5 -> 986511.18 | I7: =Cotisation!$D$21*n_intensif*I5 -> 1006241.4 | ... K7: =Cotisation!$D$21*n_intensif*K5 -> 1046893.6
A8: Chargement de gestion (+ structure fixe) | B8: =gestion_taux*(B6+B7)+gestion_fixe*B5 -> 88538.752 | C8: =gestion_taux*(C6+C7)+gestion_fixe*C5 -> 90309.527 | D8: =gestion_taux*(D6+D7)+gestion_fixe*D5 -> 92115.717 | E8: =gestion_taux*(E6+E7)+gestion_fixe*E5 -> 93958.031 | F8: =gestion_taux*(F6+F7)+gestion_fixe*F5 -> 95837.192 | G8: =gestion_taux*(G6+G7)+gestion_fixe*G5 -> 97753.936 | H8: =gestion_taux*(H6+H7)+gestion_fixe*H5 -> 99709.015 | I8: =gestion_taux*(I6+I7)+gestion_fixe*I5 -> 101703.19 | ... K8: =gestion_taux*(K6+K7)+gestion_fixe*K5 -> 105812
A9: Coûts totaux | B9: =SUM(B6:B8) -> 1564184.6 | C9: =SUM(C6:C8) -> 1595468.3 | D9: =SUM(D6:D8) -> 1627377.7 | E9: =SUM(E6:E8) -> 1659925.2 | F9: =SUM(F6:F8) -> 1693123.7 | G9: =SUM(G6:G8) -> 1726986.2 | H9: =SUM(H6:H8) -> 1761525.9 | I9: =SUM(I6:I8) -> 1796756.4 | ... K9: =SUM(K6:K8) -> 1869345.4
A10: Multiplicateur du tarif | B10: =1 -> 1 | C10: =IF(revision=1,B10*MIN(1+cap_hausse,MAX(1-cap_baisse,B9*(1+provision)/B13)),B10) -> 1.0042105 | D10: =IF(revision=1,C10*MIN(1+cap_hausse,MAX(1-cap_baisse,C9*(1+provision)/C13)),C10) -> 1.0242947 | E10: =IF(revision=1,D10*MIN(1+cap_hausse,MAX(1-cap_baisse,D9*(1+provision)/D13)),D10) -> 1.0447806 | F10: =IF(revision=1,E10*MIN(1+cap_hausse,MAX(1-cap_baisse,E9*(1+provision)/E13)),E10) -> 1.0656762 | G10: =IF(revision=1,F10*MIN(1+cap_hausse,MAX(1-cap_baisse,F9*(1+provision)/F13)),F10) -> 1.0869898 | H10: =IF(revision=1,G10*MIN(1+cap_hausse,MAX(1-cap_baisse,G9*(1+provision)/G13)),G10) -> 1.1087296 | I10: =IF(revision=1,H10*MIN(1+cap_hausse,MAX(1-cap_baisse,H9*(1+provision)/H13)),H10) -> 1.1309042 | J10: =IF(revision=1,I10*MIN(1+cap_hausse,MAX(1-cap_baisse,I9*(1+provision)/I13)),I10) -> 1.1535222 | K10: =IF(revision=1,J10*MIN(1+cap_hausse,MAX(1-cap_baisse,J9*(1+provision)/J13)),J10) -> 1.1765927
A11: Recettes, parc léger | B11: =Cotisation!$C$30*n_leger*Cotisation!$C$5*B10 -> 683603.46 | C11: =Cotisation!$C$30*n_leger*Cotisation!$C$5*C10 -> 686481.79 | D11: =Cotisation!$C$30*n_leger*Cotisation!$C$5*D10 -> 700211.43 | E11: =Cotisation!$C$30*n_leger*Cotisation!$C$5*E10 -> 714215.66 | F11: =Cotisation!$C$30*n_leger*Cotisation!$C$5*F10 -> 728499.97 | G11: =Cotisation!$C$30*n_leger*Cotisation!$C$5*G10 -> 743069.97 | H11: =Cotisation!$C$30*n_leger*Cotisation!$C$5*H10 -> 757931.37 | I11: =Cotisation!$C$30*n_leger*Cotisation!$C$5*I10 -> 773090 | ... K11: =Cotisation!$C$30*n_leger*Cotisation!$C$5*K10 -> 804322.83
A12: Recettes, parc intensif | B12: =Cotisation!$D$30*n_intensif*Cotisation!$D$5*B10 -> 998632.82 | C12: =Cotisation!$D$30*n_intensif*Cotisation!$D$5*C10 -> 1002837.6 | D12: =Cotisation!$D$30*n_intensif*Cotisation!$D$5*D10 -> 1022894.3 | E12: =Cotisation!$D$30*n_intensif*Cotisation!$D$5*E10 -> 1043352.2 | F12: =Cotisation!$D$30*n_intensif*Cotisation!$D$5*F10 -> 1064219.3 | G12: =Cotisation!$D$30*n_intensif*Cotisation!$D$5*G10 -> 1085503.7 | H12: =Cotisation!$D$30*n_intensif*Cotisation!$D$5*H10 -> 1107213.7 | I12: =Cotisation!$D$30*n_intensif*Cotisation!$D$5*I10 -> 1129358 | ... K12: =Cotisation!$D$30*n_intensif*Cotisation!$D$5*K10 -> 1174984.1
A13: Recettes totales | B13: =B11+B12 -> 1682236.3 | C13: =C11+C12 -> 1689319.4 | D13: =D11+D12 -> 1723105.8 | E13: =E11+E12 -> 1757567.9 | F13: =F11+F12 -> 1792719.2 | G13: =G11+G12 -> 1828573.6 | H13: =H11+H12 -> 1865145.1 | I13: =I11+I12 -> 1902448 | ... K13: =K11+K12 -> 1979306.9
A14: Résultat de l'année | B14: =B13-B9 -> 118051.67 | C14: =C13-C9 -> 93851.077 | D14: =D13-D9 -> 95728.098 | E14: =E13-E9 -> 97642.66 | F14: =F13-F9 -> 99595.513 | G14: =G13-G9 -> 101587.42 | H14: =H13-H9 -> 103619.17 | I14: =I13-I9 -> 105691.56 | ... K14: =K13-K9 -> 109961.49
A15: Marge | B15: =IF(B13=0,0,B14/B13) -> 0.070175439 | C15: =IF(C13=0,0,C14/C13) -> 0.055555556 | D15: =IF(D13=0,0,D14/D13) -> 0.055555556 | E15: =IF(E13=0,0,E14/E13) -> 0.055555556 | F15: =IF(F13=0,0,F14/F13) -> 0.055555556 | G15: =IF(G13=0,0,G14/G13) -> 0.055555556 | H15: =IF(H13=0,0,H14/H13) -> 0.055555556 | I15: =IF(I13=0,0,I14/I13) -> 0.055555556 | ... K15: =IF(K13=0,0,K14/K13) -> 0.055555556
A16: Réserve en fin d'année | B16: =capital_initial+B14 -> 118051.67 | C16: =B16+C14 -> 211902.75 | D16: =C16+D14 -> 307630.84 | E16: =D16+E14 -> 405273.5 | F16: =E16+F14 -> 504869.02 | G16: =F16+G14 -> 606456.44 | H16: =G16+H14 -> 710075.61 | I16: =H16+I14 -> 815767.17 | J16: =I16+J14 -> 923572.56 | K16: =J16+K14 -> 1033534
A17: Cotisation mensuelle, usage léger | B17: =Cotisation!$C$29*B10 -> 52.094877 | C17: =Cotisation!$C$29*C10 -> 52.314224 | D17: =Cotisation!$C$29*D10 -> 53.360508 | E17: =Cotisation!$C$29*E10 -> 54.427719 | F17: =Cotisation!$C$29*F10 -> 55.516273 | G17: =Cotisation!$C$29*G10 -> 56.626598 | H17: =Cotisation!$C$29*H10 -> 57.75913 | I17: =Cotisation!$C$29*I10 -> 58.914313 | ... K17: =Cotisation!$C$29*K10 -> 61.294451
A18: Cotisation mensuelle, usage intensif | B18: =Cotisation!$D$29*B10 -> 114.19017 | C18: =Cotisation!$D$29*C10 -> 114.67097 | D18: =Cotisation!$D$29*D10 -> 116.96439 | E18: =Cotisation!$D$29*E10 -> 119.30368 | F18: =Cotisation!$D$29*F10 -> 121.68975 | G18: =Cotisation!$D$29*G10 -> 124.12355 | H18: =Cotisation!$D$29*H10 -> 126.60602 | I18: =Cotisation!$D$29*I10 -> 129.13814 | ... K18: =Cotisation!$D$29*K10 -> 134.35532
A19: Versements aux ateliers (forfait, main d'œuvre, prime), par atelier | B19: =(SUM(Cotisation!$C$10:$C$12)*n_leger+SUM(Cotisation!$D$10:$D$12)*n_intensif)*B5/n_ateliers -> 20560.946 | C19: =(SUM(Cotisation!$C$10:$C$12)*n_leger+SUM(Cotisation!$D$10:$D$12)*n_intensif)*C5/n_ateliers -> 20972.165 | D19: =(SUM(Cotisation!$C$10:$C$12)*n_leger+SUM(Cotisation!$D$10:$D$12)*n_intensif)*D5/n_ateliers -> 21391.609 | E19: =(SUM(Cotisation!$C$10:$C$12)*n_leger+SUM(Cotisation!$D$10:$D$12)*n_intensif)*E5/n_ateliers -> 21819.441 | F19: =(SUM(Cotisation!$C$10:$C$12)*n_leger+SUM(Cotisation!$D$10:$D$12)*n_intensif)*F5/n_ateliers -> 22255.83 | G19: =(SUM(Cotisation!$C$10:$C$12)*n_leger+SUM(Cotisation!$D$10:$D$12)*n_intensif)*G5/n_ateliers -> 22700.946 | H19: =(SUM(Cotisation!$C$10:$C$12)*n_leger+SUM(Cotisation!$D$10:$D$12)*n_intensif)*H5/n_ateliers -> 23154.965 | I19: =(SUM(Cotisation!$C$10:$C$12)*n_leger+SUM(Cotisation!$D$10:$D$12)*n_intensif)*I5/n_ateliers -> 23618.065 | ... K19: =(SUM(Cotisation!$C$10:$C$12)*n_leger+SUM(Cotisation!$D$10:$D$12)*n_intensif)*K5/n_ateliers -> 24572.234
A20: Versements aux fabricants (rente et prime) | B20: =(Cotisation!$C$15+Cotisation!$C$16)*n_leger+(Cotisation!$D$15+Cotisation!$D$16)*n_intensif -> 196968 | C20: =(Cotisation!$C$15+Cotisation!$C$16)*n_leger+(Cotisation!$D$15+Cotisation!$D$16)*n_intensif -> 196968 | D20: =(Cotisation!$C$15+Cotisation!$C$16)*n_leger+(Cotisation!$D$15+Cotisation!$D$16)*n_intensif -> 196968 | E20: =(Cotisation!$C$15+Cotisation!$C$16)*n_leger+(Cotisation!$D$15+Cotisation!$D$16)*n_intensif -> 196968 | F20: =(Cotisation!$C$15+Cotisation!$C$16)*n_leger+(Cotisation!$D$15+Cotisation!$D$16)*n_intensif -> 196968 | G20: =(Cotisation!$C$15+Cotisation!$C$16)*n_leger+(Cotisation!$D$15+Cotisation!$D$16)*n_intensif -> 196968 | H20: =(Cotisation!$C$15+Cotisation!$C$16)*n_leger+(Cotisation!$D$15+Cotisation!$D$16)*n_intensif -> 196968 | I20: =(Cotisation!$C$15+Cotisation!$C$16)*n_leger+(Cotisation!$D$15+Cotisation!$D$16)*n_intensif -> 196968 | ... K20: =(Cotisation!$C$15+Cotisation!$C$16)*n_leger+(Cotisation!$D$15+Cotisation!$D$16)*n_intensif -> 196968
A22: Réserve minimale sur 10 ans | B22: =MIN(B16:K16) -> 118051.67
A23: Marge cumulée sur 10 ans | B23: =SUM(B14:K14)/SUM(B13:K13) -> 0.056909788

Sheet Scénarios
A1: 37 scénarios critiques — résultats Monte-Carlo
A2: Valeurs issues de simulation.py (16 940 000 trajectoires de 10 ans graine 2026) : elles ne se recalculent pas dans Excel.
A4: Code | B4: Scénario | C4: Description | D4: Ruine sur 10 ans | E4: Ruine sur 3 ans | F4: Marge moyenne | G4: Capital requis (99 %) | H4: Capital requis par vélo | I4: Tarif d'équilibre (multiplicateur) | J4: Résultat annuel moyen | K4: Pire année (1 % des cas) | L4: Réserve finale médiane | M4: Réserve finale (5 % des cas) | N4: Occupation moyenne | O4: Léger an 1 (€/mois) | P4: Cargo an 1 (€/mois) | Q4: Léger an 10, médiane (€/mois) | R4: Cargo an 10, médiane (€/mois) | S4: Cargo an 10, 95 % des cas (€/mois) | T4: Fonds collecté an 1 | U4: Revenu par atelier an 1
A5: S00 | B5: Contrôle : la page telle quelle | C5: Postes de la page seulement, parc toujours loué, tarif de la page. | D5: 0.09565 | E5: 0.09105 | F5: 0.056103915 | G5: 81431.624 | H5: 40.715812 | I5: 1.05 | J5: 63409.921 | K5: -137833.39 | L5: 635569.82 | M5: 328742.04 | N5: 1 | O5: 35.916667 | P5: 63.75 | Q5: 35.916667 | R5: 63.75 | S5: 63.75 | T5: 1129156.9 | U5: 19350.9
A6: S01 | B6: Location, tarif de la page | C6: Tous les coûts de la location, mais le tarif affiché sur la page, sans révision. | D6: 1 | E6: 1 | F6: -0.65128264 | G6: 7288388.3 | H6: 3644.1942 | I6: 1.736 | J6: -666961.9 | K6: -1069620.2 | L6: -6662756 | M6: -7098237.4 | N6: 0.9375 | O6: 35.916667 | P6: 63.75 | Q6: 35.916667 | R6: 63.75 | S6: 63.75 | T6: 1024240.6 | U6: 18260.686
A7: S02 | B7: Location, tarif recalculé (référence) | C7: Tarif recalculé sur tous les coûts de la location, révision annuelle plafonnée à ±10 %. | D7: 0.00015 | E7: 0 | F7: 0.055023426 | G7: 0 | H7: 0 | I7: 0.936 | J7: 97877.051 | K7: -246364.63 | L7: 987371.93 | M7: 769603.27 | N7: 0.92743615 | O7: 52.094877 | P7: 114.19017 | Q7: 65.511161 | R7: 125.17808 | S7: 133.80099 | T7: 1680653.5 | U7: 18260.686
A8: S03 | B8: Référence sans révision annuelle | C8: Même tarif de départ, jamais révisé pendant 10 ans (inflation 2 %). | D8: 0.65035 | E8: 0 | F8: -0.0062741997 | G8: 723114 | H8: 361.557 | I8: 1.044 | J8: -10539.647 | K8: -411874.3 | L8: -99421.899 | M8: -532802.34 | N8: 0.9375 | O8: 52.094877 | P8: 114.19017 | Q8: 52.094877 | R8: 114.19017 | S8: 114.19017 | T8: 1680653.5 | U8: 18260.686
A9: S04 | B9: Casse prématurée ×2 | C9: Deux fois plus de ruptures de cadre, moteur ou batterie que prévu. | D9: 0.0003 | E9: 0 | F9: 0.053522448 | G9: 0 | H9: 0 | I9: 0.944 | J9: 95869.896 | K9: -245624.22 | L9: 965995.53 | M9: 755107.39 | N9: 0.92385474 | O9: 52.094877 | P9: 114.19017 | Q9: 66.445374 | R9: 126.87911 | S9: 135.70928 | T9: 1680672.2 | U9: 18260.958
A10: S05 | B10: Casse prématurée ×3, coût ×2,25 | C10: Trois fois plus de casse, à 900 € l'événement (cadre ou moteur de cargo). | D10: 0.0059 | E10: 0.0012 | F10: 0.045713706 | G10: 0 | H10: 0 | I10: 0.991 | J10: 83895.212 | K10: -240011.71 | L10: 846253.63 | M10: 638225.53 | N10: 0.89710815 | O10: 52.094877 | P10: 114.19017 | Q10: 71.467706 | R10: 135.89258 | S10: 145.42496 | T10: 1680695.8 | U10: 18261.015
A11: S06 | B11: Main d'œuvre +40 % | C11: Les heures par 1 000 km sont sous-estimées de 40 %. | D11: 0.54365 | E11: 0.2424 | F11: 0.025249554 | G11: 352916.01 | H11: 176.45801 | I11: 1.142 | J11: 46308.737 | K11: -335404.95 | L11: 476075.37 | M11: 160786.34 | N11: 0.81770696 | O11: 52.094877 | P11: 114.19017 | Q11: 84.335615 | R11: 153.83665 | S11: 167.54577 | T11: 1680653.5 | U11: 22911.49
A12: S07 | B12: Pièces ×2 | C12: Pièces d'usure deux fois plus chères ou plus consommées que prévu. | D12: 0.80825 | E12: 0.62905 | F12: 0.012028222 | G12: 454755.35 | H12: 227.37768 | I12: 1.239 | J12: 22005.616 | K12: -240511.79 | L12: 258983.06 | M12: -251991.73 | N12: 0.7780149 | O12: 52.094877 | P12: 114.19017 | Q12: 80.001883 | R12: 195.74839 | S12: 244.60506 | T12: 1680653.5 | U12: 18260.686
A13: S08 | B13: Batteries à durée courte | C13: Batteries remplacées deux fois plus souvent (vélos-cargos). | D13: 0.12735 | E13: 0 | F13: 0.040958534 | G13: 193091.53 | H13: 96.545765 | I13: 1.072 | J13: 73729.265 | K13: -343388.68 | L13: 747645.16 | M13: 445145.66 | N13: 0.91742466 | O13: 52.094877 | P13: 114.19017 | Q13: 65.477451 | R13: 138.744 | S13: 148.4501 | T13: 1680653.5 | U13: 18260.686
A14: S09 | B14: Coût de fabrication réaliste, découvert après tarification | C14: Vélo-cargo électrique à 2 800 € et vélo classique à 600 €, tarif calé sur 1 170 € et 440 €. | D14: 1 | E14: 0.82475 | F14: -0.086342775 | G14: 1875592.9 | H14: 937.79644 | I14: aucun | J14: -137129.64 | K14: -611987.06 | L14: -1380818.3 | M14: -1761724.7 | N14: 0.76975692 | O14: 52.094877 | P14: 114.19017 | Q14: 69.384412 | R14: 261.24884 | S14: 269.25445 | T14: 1680653.5 | U14: 18260.686
A15: S10 | B15: Coût de fabrication réaliste, tarifé correctement | C15: Même coûts, mais connus au moment de fixer le tarif. | D15: 1 | E15: 0 | F15: -0.077323987 | G15: 1876476.2 | H15: 938.2381 | I15: aucun | J15: -121048.09 | K15: -653920.19 | L15: -1216315.2 | M15: -1712372.9 | N15: 0.75317254 | O15: 54.872858 | P15: 147.70098 | Q15: 69.112367 | R15: 269.46148 | S15: 284.6654 | T15: 2012654.3 | U15: 18260.686
A16: S11 | B16: Rente financée à 5 % | C16: Le fabricant fait payer le coût de l'argent avancé sur 8 à 10 ans. | D16: 0.00115 | E16: 0.0001 | F16: 0.050815366 | G16: 0 | H16: 0 | I16: 0.959 | J16: 92133.123 | K16: -240147.56 | L16: 929311.52 | M16: 721350.19 | N16: 0.91640846 | O16: 52.094877 | P16: 114.19017 | Q16: 67.826364 | R16: 130.74749 | S16: 139.85115 | T16: 1680653.5 | U16: 18260.686
A17: S12 | B17: Faillites de fabricants en chaîne | C17: 15 % de risque de faillite par fabricant et par an : plus de garantie, pièces orphelines. | D17: 0.00095 | E17: 0 | F17: 0.049911175 | G17: 0 | H17: 0 | I17: 0.955 | J17: 90153.092 | K17: -247886.1 | L17: 909967.5 | M17: 698642.14 | N17: 0.91868322 | O17: 52.094877 | P17: 114.19017 | Q17: 67.536014 | R17: 132.26038 | S17: 141.46663 | T17: 1680547.6 | U17: 18260.444
A18: S13 | B18: Défauts de série, faillites et vélos orphelins | C18: 10 % de défaut de série et 10 % de faillite par fabricant et par an ; 15 % des vélos orphelins réformés chaque année. | D18: 0.0027 | E18: 0.0002 | F18: 0.047003393 | G18: 0 | H18: 0 | I18: 0.977 | J18: 85185.465 | K18: -248360.85 | L18: 860719.78 | M18: 630475.54 | N18: 0.91321206 | O18: 52.094877 | P18: 114.19017 | Q18: 68.914899 | R18: 136.41835 | S18: 148.62534 | T18: 1680558.1 | U18: 18260.227
A19: S14 | B19: Vol élevé, assuré | C19: Vol à 4 % (classique) et 8 % (cargo électrique) par an, assurance à 5 % de la valeur. | D19: 0.0001 | E19: 0 | F19: 0.055552572 | G19: 0 | H19: 0 | I19: 0.92 | J19: 98375.984 | K19: -235672.34 | L19: 990240.27 | M19: 794826.41 | N19: 0.92975209 | O19: 52.094877 | P19: 114.19017 | Q19: 65.011488 | R19: 125.23097 | S19: 134.07858 | T19: 1680768.5 | U19: 18262.109
A20: S15 | B20: Vol élevé, non assuré | C20: Même vol, la SCIC s'auto-assure : la rente restante du vélo volé est soldée. | D20: 0.00025 | E20: 0.00015 | F20: 0.052160331 | G20: 0 | H20: 0 | I20: 0.948 | J20: 89826.934 | K20: -229912.73 | L20: 906367.82 | M20: 713652.57 | N20: 0.92740311 | O20: 50.12459 | P20: 109.70296 | Q20: 62.650797 | R20: 124.02386 | S20: 133.07191 | T20: 1615186.6 | U20: 18262.109
A21: S16 | B21: Vacance forte | C21: 40 % des locataires partent chaque année, un vélo vacant sur deux est reloué. | D21: 0.6143 | E21: 0.0149 | F21: 0.0028470261 | G21: 484337.41 | H21: 242.1687 | I21: aucun | J21: 4240.7026 | K21: -211375.77 | L21: 61377.495 | M21: -317214.99 | N21: 0.56365401 | O21: 52.094877 | P21: 114.19017 | Q21: 90.817891 | R21: 176.90352 | S21: 206.30549 | T21: 1280357 | U21: 14403.313
A22: S17 | B22: Fraude kilométrique massive | C22: 30 % des usagers sous-déclarent 40 % de leurs km. | D22: 0.01135 | E22: 0.0013 | F22: 0.044701074 | G22: 5220.3002 | H22: 2.6101501 | I22: 1.002 | J22: 77182.172 | K22: -246667.89 | L22: 780036.97 | M22: 565689.99 | N22: 0.89735672 | O22: 52.094877 | P22: 114.19017 | Q22: 71.434496 | R22: 137.16817 | S22: 147.5066 | T22: 1581792.9 | U22: 18260.686
A23: S18 | B23: Usage réel +30 % de km | C23: Les vélos roulent 30 % de plus que prévu (usure et km déclarés). | D23: 0.00085 | E23: 0 | F23: 0.0531917 | G23: 0 | H23: 0 | I23: 0.948 | J23: 110393.96 | K23: -315742.49 | L23: 1113275.9 | M23: 837979.02 | N23: 0.92684132 | O23: 60.578266 | P23: 133.5201 | Q23: 76.698877 | R23: 147.73054 | S23: 158.50447 | T23: 1958875.5 | U23: 21748.789
A24: S19 | B24: Impayés à 8 % | C24: Défauts de paiement quatre fois plus élevés. | D24: 0.0375 | E24: 0.006 | F24: 0.04165068 | G24: 68599.188 | H24: 34.299594 | I24: 1.033 | J24: 71566.139 | K24: -277348.44 | L24: 724983.16 | M24: 473492.79 | N24: 0.89358639 | O24: 52.094877 | P24: 114.19017 | Q24: 72.076623 | R24: 138.42237 | S24: 150.79892 | T24: 1573166.5 | U24: 18260.686
A25: S20 | B25: Inflation 5 % sans révision | C25: Inflation des coûts de 5 % par an, tarif figé. | D25: 1 | E25: 0 | F25: -0.14250932 | G25: 3131785 | H25: 1565.8925 | I25: 1.198 | J25: -239502.05 | K25: -943199.42 | L25: -2387849.8 | M25: -2905339 | N25: 0.9375 | O25: 52.094877 | P25: 114.19017 | Q25: 52.094877 | R25: 114.19017 | S25: 114.19017 | T25: 1680653.5 | U25: 18260.686
A26: S21 | B26: Primes au plafond | C26: Score moyen de 95 : les primes de durabilité coûtent plus que prévu. | D26: 0.001 | E26: 0 | F26: 0.051504399 | G26: 0 | H26: 0 | I26: 0.958 | J26: 92986.363 | K26: -252027.31 | L26: 937684.94 | M26: 723264.86 | N26: 0.91711783 | O26: 52.094877 | P26: 114.19017 | Q26: 68.238584 | R26: 129.09693 | S26: 138.05299 | T26: 1680653.5 | U26: 18642.094
A27: S22 | B27: Coûts de gestion fixes réalistes | C27: 180 000 €/an de structure (2 ETP, registre, comité) au lieu de 6 %. | D27: 0.3026 | E27: 0.08205 | F27: 0.013941058 | G27: 337615.79 | H27: 168.8079 | I27: 1.195 | J27: 24895.169 | K27: -256560.82 | L27: 265693.29 | M27: -171705.7 | N27: 0.76912266 | O27: 52.094877 | P27: 114.19017 | Q27: 104.4558 | R27: 140.69118 | S27: 151.06978 | T27: 1680653.5 | U27: 18260.686
A28: S23 | B28: Tarif unique + élasticité (spirale) | C28: Pas de segmentation : les usagers légers paient pour les intensifs et partent. | D28: 0.4089 | E28: 0 | F28: 0.007651754 | G28: 374456.16 | H28: 187.22808 | I28: aucun | J28: 11325.28 | K28: -253658.04 | L28: 109463.77 | M28: -221745.2 | N28: 0.64979288 | O28: 65.03629 | P28: 94.778052 | Q28: 106.22901 | R28: 154.80863 | S28: 172.24244 | T28: 1680670.5 | U28: 18260.686
A29: S24 | B29: Pilote 200 vélos, 2 fabricants | C29: Petit pool : 120 légers, 80 cargos, 2 fabricants, 4 ateliers. | D29: 0.0026 | E29: 0.0002 | F29: 0.053748924 | G29: 0 | H29: 0 | I29: 0.972 | J29: 9541.9143 | K29: -28114.66 | L29: 96450.733 | M29: 69389.395 | N29: 0.92678688 | O29: 52.094877 | P29: 114.19017 | Q29: 65.417248 | R29: 125.51282 | S29: 138.6272 | T29: 168113.81 | U29: 18276.436
A30: S25 | B30: Pilote 200 vélos, 2 fabricants, faillites | C30: Petit pool avec 10 % de faillite annuelle par fabricant. | D30: 0.0068 | E30: 0.0009 | F30: 0.049688712 | G30: 0 | H30: 0 | I30: 0.995 | J30: 8900.38 | K30: -29873.925 | L30: 90126.955 | M30: 61886.086 | N30: 0.92154505 | O30: 52.094877 | P30: 114.19017 | Q30: 66.712217 | R30: 130.12068 | S30: 143.82801 | T30: 168112.76 | U30: 18276.296
A31: S26 | B31: Grande échelle : 20 000 vélos | C31: Dix fois le parc de la page, 20 fabricants, 400 ateliers. | D31: 0.0002 | E31: 0 | F31: 0.05513857 | G31: 0 | H31: 0 | I31: 0.933 | J31: 981223.17 | K31: -2454107.5 | L31: 9887859.2 | M31: 7804557.7 | N31: 0.92757373 | O31: 52.094877 | P31: 114.19017 | Q31: 65.540326 | R31: 125.12046 | S31: 132.82895 | T31: 16808797 | U31: 18259.768
A32: S27 | B32: Tempête modérée | C32: Casse ×1,5, MO +20 %, vol 3 à 6 %, vacance forte, faillites 8 %, impayés 4 %. | D32: 0.63445 | E32: 0.1919 | F32: 0.011235695 | G32: 409439.48 | H32: 204.71974 | I32: 1.202 | J32: 17839.175 | K32: -267129.31 | L32: 199174.08 | M32: -185440.89 | N32: 0.69210478 | O32: 52.094877 | P32: 114.19017 | Q32: 91.316702 | R32: 168.35886 | S32: 192.64721 | T32: 1510581.6 | U32: 19076.226
A33: S28 | B33: Tempête sévère | C33: Tout ce qui peut mal tourner en même temps, vol non assuré et inflation 4 %. | D33: 1 | E33: 1 | F33: -0.31952447 | G33: 4122478.5 | H33: 2061.2392 | I33: aucun | J33: -355688.75 | K33: -635483 | L33: -3553347.7 | M33: -3955950.2 | N33: 0.48921824 | O33: 50.12459 | P33: 109.70296 | Q33: 118.19116 | R33: 258.67385 | S33: 258.67385 | T33: 1199018.6 | U33: 18812.729
A34: S29 | B34: Tempête modérée, tarifée à l'avance | C34: La tempête modérée, mais connue au moment de tarifer. | D34: 0.03735 | E34: 5e-05 | F34: 0.029911337 | G34: 137673.36 | H34: 68.836681 | I34: 1.064 | J34: 47379.173 | K34: -261415.24 | L34: 499292.63 | M34: 84183.289 | N34: 0.68611759 | O34: 59.530802 | P34: 129.7764 | Q34: 91.850827 | R34: 168.66242 | S34: 194.37671 | T34: 1720351.8 | U34: 19076.226
A35: S30 | B35: Coût de fabrication réaliste, usagers captifs | C35: Comme S10, mais les usagers (flottes pro) ne partent pas quand le prix monte. | D35: 0 | E35: 0 | F35: 0.05842682 | G35: 0 | H35: 0 | I35: 0.914 | J35: 124695.57 | K35: -224749.27 | L35: 1252442.6 | M35: 1069153.7 | N35: 0.9375 | O35: 54.872858 | P35: 147.70098 | Q35: 68.389918 | R35: 157.91741 | S35: 167.41405 | T35: 2012654.3 | U35: 18260.686
A36: S31 | B36: Tempête sévère, tarifée à l'avance, usagers captifs | C36: Le pire cas connu d'avance, sans départ des usagers : le prix nécessaire. | D36: 0.24085 | E36: 0.00015 | F36: 0.024279671 | G36: 359412.2 | H36: 179.7061 | I36: 1.108 | J36: 51080.412 | K36: -412463.58 | L36: 531817 | M36: 136192.74 | N36: 0.75338657 | O36: 72.505227 | P36: 170.7041 | Q36: 107.28221 | R36: 226.51406 | S36: 243.72613 | T36: 1808058.9 | U36: 18812.729
A37: S32 | B37: Tarif prudent (80 % d'occupation), réalité conforme | C37: Tarif calculé en supposant 80 % du parc loué au lieu de 94 % ; la réalité suit les hypothèses de référence. | D37: 0 | E37: 0 | F37: 0.062315406 | G37: 0 | H37: 0 | I37: 0.887 | J37: 111716.98 | K37: -249461.45 | L37: 1124467.9 | M37: 905581.12 | N37: 0.92752448 | O37: 54.246262 | P37: 120.54577 | Q37: 65.501561 | R37: 125.11213 | S37: 133.90218 | T37: 1765093 | U37: 18260.686
A38: S33 | B38: Tarif prudent (80 %), vacance forte | C38: Tarif prudent face à la vacance forte de S16. | D38: 0.3055 | E38: 0.0004 | F38: 0.010619571 | G38: 417992.55 | H38: 208.99627 | I38: aucun | J38: 14043.266 | K38: -211211.74 | L38: 159582.16 | M38: -224960.67 | N38: 0.56335422 | O38: 54.246262 | P38: 120.54577 | Q38: 90.750719 | R38: 176.7359 | S38: 206.57537 | T38: 1344687.2 | U38: 14403.313
A39: S34 | B39: Tarif prudent (80 %), tempête modérée | C39: Tarif prudent face à la tempête modérée de S27. | D39: 0.2608 | E39: 0.01795 | F39: 0.017986786 | G39: 306858 | H39: 153.429 | I39: 1.134 | J39: 28427.674 | K39: -266129.23 | L39: 305501.15 | M39: -88836.77 | N39: 0.68987308 | O39: 54.246262 | P39: 120.54577 | Q39: 91.473347 | R39: 168.07125 | S39: 192.32921 | T39: 1586470 | U39: 19076.226
A40: S35 | B40: Tarif prudent (80 %), pièces ×2 | C40: Tarif prudent face aux pièces sous-estimées de S07. | D40: 0.3397 | E40: 0.1194 | F40: 0.017814195 | G40: 339483.47 | H40: 169.74173 | I40: 1.173 | J40: 32379.934 | K40: -237826.75 | L40: 360387 | M40: -128455.49 | N40: 0.77723264 | O40: 54.246262 | P40: 120.54577 | Q40: 79.990352 | R40: 195.28482 | S40: 243.76509 | T40: 1765093 | U40: 18260.686
A41: S36 | B41: Tarif très prudent (70 %), tempête modérée | C41: Tarif calculé en supposant 70 % du parc loué, face à la tempête modérée. | D41: 0.07455 | E41: 0.00045 | F41: 0.025385288 | G41: 186096 | H41: 93.048002 | I41: 1.077 | J41: 40157.603 | K41: -264755.56 | L41: 424119.7 | M41: 30790.164 | N41: 0.68905477 | O41: 56.341767 | P41: 126.73629 | Q41: 91.361134 | R41: 168.02109 | S41: 193.27147 | T41: 1660387.3 | U41: 19076.226
...

Sheet Sensibilité
A1: Analyse de sensibilité globale
A2: 5 000 jeux de paramètres tirés en hypercube latin × 200 trajectoires tarif de référence et révision annuelle. Valeurs issues de simulation.py.
A4: Probabilité de ruine moyenne sur l'espace exploré | B4: 0.882043
A5: Jeux dont la ruine dépasse 5 % | B5: 0.9348
A6: Jeux dont la ruine dépasse 50 % | B6: 0.8826
A7: Marge médiane | B7: -0.17280761
A8: Capital requis (99 %), médiane des jeux | B8: 3092588.6
A9: Capital requis (99 %), 90e centile des jeux | B9: 5731522.5
A12: Rang | B12: Paramètre | C12: Minimum exploré | D12: Maximum exploré | E12: Corrélation de rang avec la marge | F12: Ruine, quintile bas | G12: Ruine, quintile haut
A13: 1 | B13: Coût de fabrication, vélo-cargo (€) | C13: 1000 | D13: 3000 | E13: -0.51642432 | F13: 0.716375 | G13: 0.9866
A14: 2 | B14: Consommation de pièces (multiplicateur) | C14: 0.5 | D14: 1.7 | E14: -0.35854832 | F14: 0.723635 | G14: 0.98166
A15: 3 | B15: Heures de main d'œuvre (multiplicateur) | C15: 0.75 | D15: 1.35 | E15: -0.32509647 | F15: 0.743065 | G15: 0.972735
A16: 4 | B16: Relocation des vélos vacants | C16: 0.55 | D16: 0.95 | E16: 0.30026241 | F16: 0.940435 | G16: 0.837655
A17: 5 | B17: Inflation | C17: 0 | D17: 0.04 | E17: 0.2778255 | F17: 0.88162 | G17: 0.903005
A18: 6 | B18: Départs de locataires par an | C18: 0.1 | D18: 0.35 | E18: -0.22204444 | F18: 0.840815 | G18: 0.919945
A19: 7 | B19: Coûts de structure fixes (€/an) | C19: 0 | D19: 150000 | E19: -0.21094507 | F19: 0.814165 | G19: 0.931775
A20: 8 | B20: Taux horaire moyen (€) | C20: 40 | D20: 58 | E20: -0.19699451 | F20: 0.80083 | G20: 0.94224
A21: 9 | B21: Kilométrage (multiplicateur) | C21: 0.7 | D21: 1.3 | E21: 0.16900827 | F21: 0.92721 | G21: 0.83562
A22: 10 | B22: Impayés | C22: 0 | D22: 0.06 | E22: -0.15863595 | F22: 0.842265 | G22: 0.913475
A23: 11 | B23: Vieillissement (heures par année d'âge) | C23: 0 | D23: 0.08 | E23: -0.12718059 | F23: 0.829635 | G23: 0.919615
A24: 12 | B24: Taux de financement de la rente | C24: 0 | D24: 0.06 | E24: -0.12416809 | F24: 0.851115 | G24: 0.898255
... A34: 22 | B34: Défauts de série (par fabricant et par an) | C34: 0 | D34: 0.08 | E34: -0.0061093387 | F34: 0.86806 | G34: 0.889785
A37: Probabilité de ruine selon les deux paramètres les plus influents
A38: Lignes : Coût de fabrication, vélo-cargo (€) ; colonnes : Consommation de pièces (multiplicateur)
C39: 0,50 à 0,80 | D39: 0,80 à 1,10 | E39: 1,10 à 1,40 | F39: 1,40 à 1,70
B40: 1 000 à 1 500 | C40: 0.47322485 | D40: 0.72535032 | E40: 0.83488255 | F40: 0.93556667
B41: 1 500 à 2 000 | C41: 0.67857143 | D41: 0.83090343 | E41: 0.92598746 | F41: 0.98389241
B42: 2 000 à 2 500 | C42: 0.87373355 | D42: 0.95609524 | E42: 0.98279935 | F42: 0.99822981
B43: 2 500 à 3 000 | C43: 0.94171975 | D43: 0.9901 | E43: 0.99966049 | F43: 1

Sheet Vacance prudente
A1: Tarifer avec une vacance prudente
A2: Le tarif de départ est calculé en supposant un taux d'occupation plus bas que l'équilibre (94 %). La réalité est ensuite tirée au sort selon cinq situations. Valeurs issues de simulation.py.
A4: Usagers sensibles au prix (élasticité 1)
A5: Occupation supposée | B5: Léger (€/mois) | C5: Cargo (€/mois) | D5: Ruine — Réalité conforme | E5: Ruine — Vacance forte (S16) | F5: Ruine — Tempête modérée (S27) | G5: Ruine — Pièces ×2 (S07) | H5: Ruine — Main d'œuvre +40 % (S06) | I5: Occupation réelle — Réalité conforme | J5: Occupation réelle — Vacance forte (S16) | K5: Occupation réelle — Tempête modérée (S27) | L5: Occupation réelle — Pièces ×2 (S07) | M5: Occupation réelle — Main d'œuvre +40 % (S06)
A6: 94 % (référence) | B6: 52.094877 | C6: 114.19017 | D6: 0.0002 | E6: 0.6109 | F6: 0.6332 | G6: 0.8103 | H6: 0.5395 | I6: 0.92736224 | J6: 0.56402648 | K6: 0.69188584 | L6: 0.77802426 | M6: 0.81758215
A7: 88 % | B7: 52.912759 | C7: 116.60635 | D7: 0 | E7: 0.4906 | F7: 0.4826 | G7: 0.617 | H7: 0.3767 | I7: 0.92738756 | J7: 0.56375936 | K7: 0.69068737 | L7: 0.77744358 | M7: 0.81691135
A8: 80 % | B8: 54.246262 | C8: 120.54577 | D8: 0 | E8: 0.2985 | F8: 0.267 | G8: 0.3386 | H8: 0.1743 | I8: 0.92753648 | J8: 0.56339858 | K8: 0.68938291 | L8: 0.77702119 | M8: 0.8162025
A9: 70 % | B9: 56.341767 | C9: 126.73629 | D9: 0 | E9: 0.1333 | F9: 0.079 | G9: 0.1248 | H9: 0.0352 | I9: 0.927581 | J9: 0.56387248 | K9: 0.688886 | L9: 0.77752396 | M9: 0.8159681
A11: Usagers captifs (élasticité 0)
A12: Occupation supposée | B12: Léger (€/mois) | C12: Cargo (€/mois) | D12: Ruine — Réalité conforme | E12: Ruine — Vacance forte (S16) | F12: Ruine — Tempête modérée (S27) | G12: Ruine — Pièces ×2 (S07) | H12: Ruine — Main d'œuvre +40 % (S06) | I12: Occupation réelle — Réalité conforme | J12: Occupation réelle — Vacance forte (S16) | K12: Occupation réelle — Tempête modérée (S27) | L12: Occupation réelle — Pièces ×2 (S07) | M12: Occupation réelle — Main d'œuvre +40 % (S06)
A13: 94 % (référence) | B13: 52.094877 | C13: 114.19017 | D13: 0 | E13: 0.0419 | F13: 0.2561 | G13: 0.6118 | H13: 0.3492 | I13: 0.93748979 | J13: 0.71429005 | K13: 0.86092024 | L13: 0.93748979 | M13: 0.93748979
A14: 88 % | B14: 52.912759 | C14: 116.60635 | D14: 0 | E14: 0.0149 | F14: 0.1304 | G14: 0.3575 | H14: 0.2103 | I14: 0.93748979 | J14: 0.71429005 | K14: 0.86092024 | L14: 0.93748979 | M14: 0.93748979
A15: 80 % | B15: 54.246262 | C15: 120.54577 | D15: 0 | E15: 0.0031 | F15: 0.0378 | G15: 0.1023 | H15: 0.077 | I15: 0.93748979 | J15: 0.71429005 | K15: 0.86092024 | L15: 0.93748979 | M15: 0.93748979
A16: 70 % | B16: 56.341767 | C16: 126.73629 | D16: 0 | E16: 0.0003 | F16: 0.0046 | G16: 0.0085 | H16: 0.0107 | I16: 0.93748979 | J16: 0.71429005 | K16: 0.86092024 | L16: 0.93748979 | M16: 0.93748979
A18: Lecture : supposer 80 % d'occupation au lieu de 94 % relève les prix d'environ 5 % et réduit fortement le risque dans les tempêtes ; la révision annuelle fait ensuite redescendre le tarif si la vacance ne se produit pas.

Sheet Argumentaire
A1: Pourquoi louer à Pignon commun plutôt qu'ailleurs
A2: Arguments de la page de présentation et du registre des acteurs (docs/acteurs.md). Les prix Pignon commun sont liés à la feuille Cotisation.
A4: Comparaison avec les autres solutions
A5: Critère | B5: Pignon commun | C5: Acheter son vélo | D5: Loueur privé par abonnement | E5: Location publique (type Véligo)
A6: Propriétaire du vélo | B6: La coopérative, dont l'usager est sociétaire | C6: L'usager | D6: L'entreprise de location | E6: La collectivité, via un exploitant
A7: Ce que paie l'usager | B7: Une part fixe et une part au kilomètre : l'usure qu'il cause | C7: Le vélo d'avance, puis chaque réparation | D7: Un forfait mensuel | E7: Un forfait mensuel subventionné
A8: Durée | B8: Engagement minimal de 12 à 24 mois, puis sans limite | C8: Sans limite | D8: Selon l'offre | E8: 3 à 12 mois
A9: Le fabricant est payé | B9: Par une rente sur la durée de vie, avec une prime s'il dure | C9: À la vente | D9: À la vente de la flotte au loueur | E9: À la vente de la flotte
A10: Le réparateur est payé | B10: Forfait de suivi et prime de durabilité, jamais de marge sur les pièces | C10: À chaque intervention | D10: Par le loueur, selon son organisation | E10: Par l'exploitant
A11: Qui fixe le prix | B11: La coopérative, sur des coûts publiés et révisés chaque année | C11: Le marché | D11: L'entreprise | E11: La collectivité
A12: L'excédent va | B12: Dans la coopérative : baisse du tarif ou réserve commune | C12: — | D12: À l'entreprise et à ses actionnaires | E12: Au service public, financé en partie par l'impôt
A13: Suivi du vélo | B13: Contrôles préventifs selon le kilométrage, historique pièce par pièce | C13: À l'usager d'y penser | D13: Entretien par le loueur | E13: Entretien par l'exploitant
A14: En fin de contrat | B14: Rendu, reconditionné et reloué ; pièces valides au stock commun | C14: Revendu | D14: Rendu | E14: Rendu
A16: Prix mensuels indicatifs
A17: Usage | B17: Pignon commun (€/mois) | C17: Coût de possession estimé (€/mois) | D17: Véligo (€/mois) | E17: Écart Pignon commun / possession
A18: Léger, vélo classique | B18: =Cotisation!C29 -> 52.094877 | C18: 22 | D18: 10 | E18: =B18/C18-1 -> 1.367949
A19: Intensif, vélo-cargo électrique | B19: =Cotisation!D29 -> 114.19017 | C19: 110 | D19: 88 | E19: =B19/C19-1 -> 0.038092471
A20: Coût de possession et Véligo : valeurs saisies (bleu), modifiables. Voir les commentaires des cellules.
A22: Les deux faiblesses d'un loueur classique
A23: Faiblesse | B23: Pourquoi | C23: Réponse de Pignon commun
A24: Il loue des vélos qu'il n'a pas conçus | B24: Rarement fabricant, il achète sa flotte à des fabricants payés à la vente et la fait réparer par des ateliers payés à l'intervention : des acteurs dont les intérêts ne vont pas forcément vers la durée de vie. | C24: Fabricants, réparateurs et usagers sont dans la même coopérative et payés par le même fonds, sur le même résultat : la durée de vie. Rente et prime pour le fabricant, prime aux kilomètres sans panne pour le réparateur, pièces standard et documentées imposées par le label.
A25: Un vélo qui n'est pas le sien, on le ménage moins | B25: L'usager ne supporte ni l'usure ni la revente. Le loueur n'a que la caution et la facture de dégâts, une fois le mal fait. | C25: Part au kilomètre qui fait payer l'usure réelle, négligence facturée hors du fonds, état des lieux daté à l'entrée et à la sortie, engagement de signaler avant la panne, conseil d'entretien. Surtout, l'éco-usager est sociétaire : le parc qu'il abîme est en partie le sien, et chaque réparation évitée pèse sur le tarif qu'il vote.
A27: Les cinq raisons de choisir Pignon commun
A28: 1. Personne ne gagne à ce que le vélo casse | B28: Ni le fabricant, payé tant que le vélo roule, ni le réparateur, primé sur les kilomètres sans panne, ni la coopérative, sans actionnaire.
A29: 2. On paie l'usure qu'on cause | B29: La part au kilomètre suit l'usage réel : un mois où l'on roule peu coûte moins cher.
A30: 3. On a son mot à dire sur le prix | B30: Tarif construit sur des coûts publiés, voté et révisé chaque année ; la provision non consommée fait baisser le prix.
A31: 4. Moins d'arrêts, pas d'avance | B31: Pas de vélo-cargo à 5 000 € à financer, entretien planifié avant la panne, casse prématurée garantie, atelier noté sur le délai de remise en service.
A32: 5. La cotisation construit une filière | B32: Fabricants de pièces réparables, ateliers de proximité, vélo reconditionné et reloué avec son historique.
A34: Objections attendues
A35: Objection | B35: Réponse
A36: « C'est un loueur de plus. » | B36: Un loueur subit la conception de ses vélos et la négligence de ses clients ; Pignon commun aligne fabricants, réparateurs et usagers sur la durée de vie.
A37: « Véligo est moins cher. » | B37: Véligo est subventionné et limité à 3 à 12 mois : c'est une offre d'essai. Pignon commun vise l'usage durable, sans limite de durée, avec une gouvernance partagée.
A38: « Posséder son vélo coûte moins cher. » | B38: Vrai pour un usage léger (voir le tableau des prix). La cible prioritaire est l'usage intensif, où le prix rejoint le coût de possession, avec le service en plus.
A39: « Les usagers vont abîmer des vélos qui ne sont pas à eux. » | B39: Le risque existe dans toute location ; Pignon commun y oppose la part au kilomètre, la négligence facturée, l'état des lieux et le statut de sociétaire. À vérifier en pilote avec les données de Véligo.
A40: « Qui garantit que le fonds tient ? » | B40: La simulation économique : scénarios critiques, révision annuelle obligatoire, tarif de démarrage prudent et réserve d'environ 205 € par vélo.

Sheet Acteurs
A1: Acteurs à rencontrer et suivi des contacts
A2: Détail des fiches dans docs/acteurs.md. Les colonnes sur fond jaune sont à remplir au fil des rencontres ; la ligne d'exemple montre le format attendu.
A4: Priorité | B4: Catégorie | C4: Acteur | D4: À demander | E4: Argument à mettre en avant | F4: Contact | G4: Date | H4: Résultat | I4: Prochaine étape
A5: 1 | B5: Droit et assurance | C5: Juriste spécialisé | D5: La location suffit-elle à écarter la requalification en assurance ? | E5: Le vélo appartient à la SCIC, qui entretient son propre parc comme un loueur de flotte.
A6: 1 | B6: Droit et assurance | C6: Mutuelle d'assurance de l'ESS | D6: Prix de l'assurance vol d'un parc de 2 000 vélos (simulation : 5 % de la valeur par an) | E6: Les garde-fous contre la négligence réduisent la sinistralité d'un parc loué.
A7: 1 | B7: Financeurs | C7: Ecologic | D7: Une réparation payée par une SCIC propriétaire ouvre-t-elle droit au Bonus Répar Cycle ? | E7: La réparation est au cœur du modèle : le réparateur est payé pour éviter la panne.
A8: 2 | B8: Fabricants | C8: Douze Cycles | D8: Rente sur 8 à 10 ans ? Coût de fabrication réel d'un cargo labellisé ? Garantie de disponibilité des pièces ? | E8: Revenu indépendant des ventes, client qui paie la durabilité, voix dans la gouvernance. Déjà en logique de service avec Ecovelo.
A9: 2 | B9: Ateliers | C9: La Fabrique des Cyclistes | D9: Être l'atelier pilote ; heures réelles par vélo et par an | E9: Revenu socle sans malus, prime de durabilité, aucune dépendance à la marge sur les pièces : payé pour éviter la panne.
A10: 3 | B10: Financeurs | C10: ADEME | D10: Financer l'étude de faisabilité et le pilote (dispositif EFC 2026) | E10: Un loueur classique reste dans l'économie de la vente ; Pignon commun paie sur la durée de vie : c'est l'économie de la fonctionnalité.
A11: 4 | B11: Collectivités | C11: Île-de-France Mobilités et Cyclonova (Véligo) | D11: Taux de casse, vol, vacance, rotation ; part des réparations due à la négligence | E11: Se présenter en relais de Véligo, pas en concurrent ; leurs données testent l'argument sur la négligence.
A12: 4 | B12: Usagers | C12: Les Boîtes à Vélo | D12: Coût réel de possession d'un vélo-cargo ; disposition à payer un service complet | E12: Pas de vélo à 5 000 € à avancer, moins de jours d'arrêt, casse garantie : le cœur de cible.
A13: 5 | B13: Montage | C13: CG Scop et union régionale | D13: Structurer les trois collèges et financer un comité technique indépendant | E13: Une SCIC où chaque collège vote, au service d'un bien commun.
A14: 5 | B14: Théorie | C14: ATEMIS et IEEFC | D14: Relire le modèle avant le dossier ADEME | E14: Un cas concret d'économie de la fonctionnalité et de la coopération dans le vélo.
A15: — | B15: Fabricants | C15: Arcade Cycles | D15: Mêmes questions que pour Douze Cycles | E15: Revenu stable dans une filière en surcapacité.
A16: — | B16: Fabricants | C16: Manufacture Française du Cycle | D16: Mêmes questions que pour Douze Cycles | E16: Rôle de perma-fabricant sous-traitant payé sur la durée.
A17: — | B17: Fabricants | C17: Lapierre | D17: Conversation stratégique, pas partenaire unique | E17: Un modèle économique autonome, recherché pendant le redressement judiciaire.
A18: — | B18: Ateliers | C18: VELOOP | D18: Parcours de reconditionnement et stock de pièces commun | E18: Le vélo rendu est reconditionné et reloué, ses pièces retournent au stock.
A19: — | B19: Ateliers | C19: Mobilians et OPCO Mobilités | D19: Reconnaissance des niveaux N1 à N3 ; financement de la formation | E19: Un métier de réparateur revalorisé, payé pour la durée de vie obtenue.
A20: — | B20: Usagers | C20: FUB | D20: Données sur le vol ; regard des usagers | E20: Transparence sur l'usage léger, pour lequel posséder son vélo reste moins cher.
A22: Exemple | C22: Nom de l'acteur | F22: Prénom Nom, fonction | G22: 30/09/2026 | H22: Intéressé, attend le dossier | I22: Envoyer la simulation avant le 15/10
